Workbook

Sheet Grunnspill
A1: Navn | B1: Gruppe | C1: Gruppe | D1: Nasjon / lag | E1: Plass (1 til 4) | F1: Beste treer (merk m/ 1) | K1: Enere | L1: =COUNTIFS(E:E,1) -> 0 | M1: =IF(L1=12,"OK","Ikke ferdig") -> Ikke ferdig
H2: Sortert tabell | K2: Toere | L2: =COUNTIFS(E:E,2) -> 0 | M2: =IF(L2=12,"OK","Ikke ferdig") -> Ikke ferdig
K3: Beste treere | L3: =COUNTIFS(F:F,1) -> 0 | M3: =IF(L3=8,"OK","Ikke ferdig") -> Ikke ferdig
A4: =IF(E4<3,E4,IF(F4=1,E4,""))&B4 -> A | B4: A | C4: =+$B4 -> A | D4: Mexico | G4: =IF(AND(F4=1,E4<>3),"skjerpings på treerne","") | H4: =+$B4 -> A | I4: {=_xlfn.SORTBY(D4:D7,E4:E7)} -> Mexico | K4: =+G4
A5: =IF(E5<3,E5,IF(F5=1,E5,""))&B5 -> A | B5: A | D5: Sør-Afrika | G5: =IF(AND(F5=1,E5<>3),"skjerpings på treerne","") | I5: Sør-Afrika | K5: =+G5
A6: =IF(E6<3,E6,IF(F6=1,E6,""))&B6 -> A | B6: A | D6: Sør-Korea | G6: =IF(AND(F6=1,E6<>3),"skjerpings på treerne","") | I6: Sør-Korea | K6: =+G6
A7: =IF(E7<3,E7,IF(F7=1,E7,""))&B7 -> A | B7: A | D7: Tsjekkia | G7: =IF(AND(F7=1,E7<>3),"skjerpings på treerne","") | I7: Tsjekkia | K7: =+G7
A8: =IF(E8<3,E8,IF(F8=1,E8,""))&B8 -> B | B8: B | C8: =+$B8 -> B | D8: Canada | G8: =IF(AND(F8=1,E8<>3),"skjerpings på treerne","") | H8: =+$B8 -> B | I8: {=_xlfn.SORTBY(D8:D11,E8:E11)} -> Canada | K8: =+G8
A9: =IF(E9<3,E9,IF(F9=1,E9,""))&B9 -> B | B9: B | D9: Bosnia-Hercegovina | G9: =IF(AND(F9=1,E9<>3),"skjerpings på treerne","") | I9: Bosnia-Hercegovina | K9: =+G9
A10: =IF(E10<3,E10,IF(F10=1,E10,""))&B10 -> B | B10: B | D10: Qatar | G10: =IF(AND(F10=1,E10<>3),"skjerpings på treerne","") | I10: Qatar | K10: =+G10
A11: =IF(E11<3,E11,IF(F11=1,E11,""))&B11 -> B | B11: B | D11: Sveits | G11: =IF(AND(F11=1,E11<>3),"skjerpings på treerne","") | I11: Sveits | K11: =+G11
A12: =IF(E12<3,E12,IF(F12=1,E12,""))&B12 -> C | B12: C | C12: =+$B12 -> C | D12: Brasil | G12: =IF(AND(F12=1,E12<>3),"skjerpings på treerne","") | H12: =+$B12 -> C | I12: {=_xlfn.SORTBY(D12:D15,E12:E15)} -> Brasil | K12: =+G12
A13: =IF(E13<3,E13,IF(F13=1,E13,""))&B13 -> C | B13: C | D13: Marokko | G13: =IF(AND(F13=1,E13<>3),"skjerpings på treerne","") | I13: Marokko | K13: =+G13
A14: =IF(E14<3,E14,IF(F14=1,E14,""))&B14 -> C | B14: C | D14: Skottland | G14: =IF(AND(F14=1,E14<>3),"skjerpings på treerne","") | I14: Skottland | K14: =+G14
A15: =IF(E15<3,E15,IF(F15=1,E15,""))&B15 -> C | B15: C | D15: Haiti | G15: =IF(AND(F15=1,E15<>3),"skjerpings på treerne","") | I15: Haiti | K15: =+G15
A16: =IF(E16<3,E16,IF(F16=1,E16,""))&B16 -> D | B16: D | C16: =+$B16 -> D | D16: USA | G16: =IF(AND(F16=1,E16<>3),"skjerpings på treerne","") | H16: =+$B16 -> D | I16: {=_xlfn.SORTBY(D16:D19,E16:E19)} -> USA | K16: =+G16
A17: =IF(E17<3,E17,IF(F17=1,E17,""))&B17 -> D | B17: D | D17: Paraguay | G17: =IF(AND(F17=1,E17<>3),"skjerpings på treerne","") | I17: Paraguay | K17: =+G17
A18: =IF(E18<3,E18,IF(F18=1,E18,""))&B18 -> D | B18: D | D18: Australia | G18: =IF(AND(F18=1,E18<>3),"skjerpings på treerne","") | I18: Australia | K18: =+G18
A19: =IF(E19<3,E19,IF(F19=1,E19,""))&B19 -> D | B19: D | D19: Tyrkia | G19: =IF(AND(F19=1,E19<>3),"skjerpings på treerne","") | I19: Tyrkia | K19: =+G19
A20: =IF(E20<3,E20,IF(F20=1,E20,""))&B20 -> E | B20: E | C20: =+$B20 -> E | D20: Tyskland | G20: =IF(AND(F20=1,E20<>3),"skjerpings på treerne","") | H20: =+$B20 -> E | I20: {=_xlfn.SORTBY(D20:D23,E20:E23)} -> Tyskland | K20: =+G20
A21: =IF(E21<3,E21,IF(F21=1,E21,""))&B21 -> E | B21: E | D21: Ecuador | G21: =IF(AND(F21=1,E21<>3),"skjerpings på treerne","") | I21: Ecuador | K21: =+G21
A22: =IF(E22<3,E22,IF(F22=1,E22,""))&B22 -> E | B22: E | D22: Elfenbenskysten | G22: =IF(AND(F22=1,E22<>3),"skjerpings på treerne","") | I22: Elfenbenskysten | K22: =+G22
A23: =IF(E23<3,E23,IF(F23=1,E23,""))&B23 -> E | B23: E | D23: Curaçao | G23: =IF(AND(F23=1,E23<>3),"skjerpings på treerne","") | I23: Curaçao | K23: =+G23
A24: =IF(E24<3,E24,IF(F24=1,E24,""))&B24 -> F | B24: F | C24: =+$B24 -> F | D24: Nederland | G24: =IF(AND(F24=1,E24<>3),"skjerpings på treerne","") | H24: =+$B24 -> F | I24: {=_xlfn.SORTBY(D24:D27,E24:E27)} -> Nederland | K24: =+G24
A25: =IF(E25<3,E25,IF(F25=1,E25,""))&B25 -> F | B25: F | D25: Japan | G25: =IF(AND(F25=1,E25<>3),"skjerpings på treerne","") | I25: Japan | K25: =+G25
A26: =IF(E26<3,E26,IF(F26=1,E26,""))&B26 -> F | B26: F | D26: Tunisia | G26: =IF(AND(F26=1,E26<>3),"skjerpings på treerne","") | I26: Tunisia | K26: =+G26
A27: =IF(E27<3,E27,IF(F27=1,E27,""))&B27 -> F | B27: F | D27: Sverige | G27: =IF(AND(F27=1,E27<>3),"skjerpings på treerne","") | I27: Sverige | K27: =+G27
A28: =IF(E28<3,E28,IF(F28=1,E28,""))&B28 -> G | B28: G | C28: =+$B28 -> G | D28: Belgia | G28: =IF(AND(F28=1,E28<>3),"skjerpings på treerne","") | H28: =+$B28 -> G | I28: {=_xlfn.SORTBY(D28:D31,E28:E31)} -> Belgia | K28: =+G28
A29: =IF(E29<3,E29,IF(F29=1,E29,""))&B29 -> G | B29: G | D29: Iran | G29: =IF(AND(F29=1,E29<>3),"skjerpings på treerne","") | I29: Iran | K29: =+G29
A30: =IF(E30<3,E30,IF(F30=1,E30,""))&B30 -> G | B30: G | D30: Egypt | G30: =IF(AND(F30=1,E30<>3),"skjerpings på treerne","") | I30: Egypt | K30: =+G30
A31: =IF(E31<3,E31,IF(F31=1,E31,""))&B31 -> G | B31: G | D31: New Zealand | G31: =IF(AND(F31=1,E31<>3),"skjerpings på treerne","") | I31: New Zealand | K31: =+G31
A32: =IF(E32<3,E32,IF(F32=1,E32,""))&B32 -> H | B32: H | C32: =+$B32 -> H | D32: Spania | G32: =IF(AND(F32=1,E32<>3),"skjerpings på treerne","") | H32: =+$B32 -> H | I32: {=_xlfn.SORTBY(D32:D35,E32:E35)} -> Spania | K32: =+G32
A33: =IF(E33<3,E33,IF(F33=1,E33,""))&B33 -> H | B33: H | D33: Uruguay | G33: =IF(AND(F33=1,E33<>3),"skjerpings på treerne","") | I33: Uruguay | K33: =+G33
A34: =IF(E34<3,E34,IF(F34=1,E34,""))&B34 -> H | B34: H | D34: Saudi-Arabia | G34: =IF(AND(F34=1,E34<>3),"skjerpings på treerne","") | I34: Saudi-Arabia | K34: =+G34
A35: =IF(E35<3,E35,IF(F35=1,E35,""))&B35 -> H | B35: H | D35: Kapp Verde | G35: =IF(AND(F35=1,E35<>3),"skjerpings på treerne","") | I35: Kapp Verde | K35: =+G35
A36: =IF(E36<3,E36,IF(F36=1,E36,""))&B36 -> I | B36: I | C36: =+$B36 -> I | D36: Frankrike | G36: =IF(AND(F36=1,E36<>3),"skjerpings på treerne","") | H36: =+$B36 -> I | I36: {=_xlfn.SORTBY(D36:D39,E36:E39)} -> Frankrike | K36: =+G36
A37: =IF(E37<3,E37,IF(F37=1,E37,""))&B37 -> I | B37: I | D37: Senegal | G37: =IF(AND(F37=1,E37<>3),"skjerpings på treerne","") | I37: Senegal | K37: =+G37
A38: =IF(E38<3,E38,IF(F38=1,E38,""))&B38 -> I | B38: I | D38: Norge | G38: =IF(AND(F38=1,E38<>3),"skjerpings på treerne","") | I38: Norge | K38: =+G38
A39: =IF(E39<3,E39,IF(F39=1,E39,""))&B39 -> I | B39: I | D39: Irak | G39: =IF(AND(F39=1,E39<>3),"skjerpings på treerne","") | I39: Irak | K39: =+G39
A40: =IF(E40<3,E40,IF(F40=1,E40,""))&B40 -> J | B40: J | C40: =+$B40 -> J | D40: Argentina | G40: =IF(AND(F40=1,E40<>3),"skjerpings på treerne","") | H40: =+$B40 -> J | I40: {=_xlfn.SORTBY(D40:D43,E40:E43)} -> Argentina | K40: =+G40
...

Sheet 16f
A1: Kamp | B1: H | C1: B | D1: Hjemme | E1: Borte | F1: HB | G1: Vinner
A2: 73 | B2: 2A | C2: 2B | D2: {=_xlfn.XLOOKUP(B2:B17,Grunnspill!$A:$A,Grunnspill!$D:$D,"-")} -> - | E2: {=_xlfn.XLOOKUP(C2:C17,Grunnspill!$A:$A,Grunnspill!$D:$D,"-")} -> - | G2: =IF(ISBLANK(F2),"",IF(F2="H",D2,E2))
A3: 74 | B3: 1E | C3: =_xlfn.XLOOKUP('16f'!B3,Annex!$B$1:$I$1,Annex!$B$2:$I$2) -> v åtte | D3: - | E3: - | G3: =IF(ISBLANK(F3),"",IF(F3="H",D3,E3)) | H3: =+C3 -> v åtte
A4: 75 | B4: 1F | C4: 2C | D4: - | E4: - | G4: =IF(ISBLANK(F4),"",IF(F4="H",D4,E4))
A5: 76 | B5: 1C | C5: 2F | D5: - | E5: - | G5: =IF(ISBLANK(F5),"",IF(F5="H",D5,E5))
A6: 77 | B6: 1I | C6: =_xlfn.XLOOKUP('16f'!B6,Annex!$B$1:$I$1,Annex!$B$2:$I$2) -> treere | D6: - | E6: - | G6: =IF(ISBLANK(F6),"",IF(F6="H",D6,E6)) | H6: =+C6 -> treere
A7: 78 | B7: 2E | C7: 2I | D7: - | E7: - | G7: =IF(ISBLANK(F7),"",IF(F7="H",D7,E7))
A8: 79 | B8: 1A | C8: =_xlfn.XLOOKUP('16f'!B8,Annex!$B$1:$I$1,Annex!$B$2:$I$2) -> Avven | D8: - | E8: - | G8: =IF(ISBLANK(F8),"",IF(F8="H",D8,E8)) | H8: =+C8 -> Avven
A9: 80 | B9: 1L | C9: =_xlfn.XLOOKUP('16f'!B9,Annex!$B$1:$I$1,Annex!$B$2:$I$2) -> å! Tipp | D9: - | E9: - | G9: =IF(ISBLANK(F9),"",IF(F9="H",D9,E9)) | H9: =+C9 -> å! Tipp
A10: 81 | B10: 1D | C10: =_xlfn.XLOOKUP('16f'!B10,Annex!$B$1:$I$1,Annex!$B$2:$I$2) -> t valg a | D10: - | E10: - | G10: =IF(ISBLANK(F10),"",IF(F10="H",D10,E10)) | H10: =+C10 -> t valg a
A11: 82 | B11: 1G | C11: =_xlfn.XLOOKUP('16f'!B11,Annex!$B$1:$I$1,Annex!$B$2:$I$2) -> beste | D11: - | E11: - | G11: =IF(ISBLANK(F11),"",IF(F11="H",D11,E11)) | H11: =+C11 -> beste
A12: 83 | B12: 2K | C12: 2L | D12: - | E12: - | G12: =IF(ISBLANK(F12),"",IF(F12="H",D12,E12))
A13: 84 | B13: 1H | C13: 2J | D13: - | E13: - | G13: =IF(ISBLANK(F13),"",IF(F13="H",D13,E13))
A14: 85 | B14: 1B | C14: =_xlfn.XLOOKUP('16f'!B14,Annex!$B$1:$I$1,Annex!$B$2:$I$2) -> ter dit | D14: - | E14: - | G14: =IF(ISBLANK(F14),"",IF(F14="H",D14,E14)) | H14: =+C14 -> ter dit
A15: 86 | B15: 1J | C15: 2H | D15: - | E15: - | G15: =IF(ISBLANK(F15),"",IF(F15="H",D15,E15))
A16: 87 | B16: 1K | C16: =_xlfn.XLOOKUP('16f'!B16,Annex!$B$1:$I$1,Annex!$B$2:$I$2) -> . Stå p | D16: - | E16: - | G16: =IF(ISBLANK(F16),"",IF(F16="H",D16,E16)) | H16: =+C16 -> . Stå p
A17: 88 | B17: 2D | C17: 2G | D17: - | E17: - | G17: =IF(ISBLANK(F17),"",IF(F17="H",D17,E17))

Sheet 8f
A1: Kamp | B1: H | C1: B | D1: Hjemme | E1: Borte | F1: HB | G1: Vinner
A2: 89 | B2: 73 | C2: 75 | D2: {=_xlfn.XLOOKUP(B2:B9,'16f'!$A:$A,'16f'!$G:$G)} | E2: {=_xlfn.XLOOKUP(C2:C9,'16f'!$A:$A,'16f'!$G:$G)} | G2: =IF(ISBLANK(F2),"",IF(F2="H",D2,E2))
A3: 90 | B3: 74 | C3: 77 | G3: =IF(ISBLANK(F3),"",IF(F3="H",D3,E3))
A4: 91 | B4: 76 | C4: 78 | G4: =IF(ISBLANK(F4),"",IF(F4="H",D4,E4))
A5: 92 | B5: 79 | C5: 80 | G5: =IF(ISBLANK(F5),"",IF(F5="H",D5,E5))
A6: 93 | B6: 83 | C6: 84 | G6: =IF(ISBLANK(F6),"",IF(F6="H",D6,E6))
A7: 94 | B7: 81 | C7: 82 | G7: =IF(ISBLANK(F7),"",IF(F7="H",D7,E7))
A8: 95 | B8: 86 | C8: 88 | G8: =IF(ISBLANK(F8),"",IF(F8="H",D8,E8))
A9: 96 | B9: 85 | C9: 87 | G9: =IF(ISBLANK(F9),"",IF(F9="H",D9,E9))

Sheet 4f
A1: Kamp | B1: H | C1: B | D1: Hjemme | E1: Borte | F1: HB | G1: Vinner
A2: 97 | B2: 89 | C2: 90 | D2: {=_xlfn.XLOOKUP(B2:B5,'8f'!$A:$A,'8f'!$G:$G)} | E2: {=_xlfn.XLOOKUP(C2:C5,'8f'!$A:$A,'8f'!$G:$G)} | G2: =IF(ISBLANK(F2),"",IF(F2="H",D2,E2))
A3: 98 | B3: 93 | C3: 94 | G3: =IF(ISBLANK(F3),"",IF(F3="H",D3,E3))
A4: 99 | B4: 91 | C4: 92 | G4: =IF(ISBLANK(F4),"",IF(F4="H",D4,E4))
A5: 100 | B5: 95 | C5: 96 | G5: =IF(ISBLANK(F5),"",IF(F5="H",D5,E5))

Sheet 2f
A1: Kamp | B1: H | C1: B | D1: Hjemme | E1: Borte | F1: HB | G1: Vinner
A2: 101 | B2: {=_xlfn.SEQUENCE(2,2,97,1)} -> 97 | C2: 98 | D2: {=_xlfn.XLOOKUP(B2:B3,'4f'!$A:$A,'4f'!$G:$G)} | E2: {=_xlfn.XLOOKUP(C2:C3,'4f'!$A:$A,'4f'!$G:$G)} | G2: =IF(ISBLANK(F2),"",IF(F2="H",D2,E2))
A3: 102 | B3: 99 | C3: 100 | G3: =IF(ISBLANK(F3),"",IF(F3="H",D3,E3))

Sheet Finale
A1: Kamp | B1: H | C1: B | D1: Hjemme | E1: Borte | F1: HB | G1: Vinner
A2: 104 | B2: {=_xlfn.SEQUENCE(1,2,101,1)} -> 101 | C2: 102 | D2: {=_xlfn.XLOOKUP(B2:B2,'2f'!$A:$A,'2f'!$G:$G)} | E2: {=_xlfn.XLOOKUP(C2:C2,'2f'!$A:$A,'2f'!$G:$G)} | G2: =IF(ISBLANK(F2),"",IF(F2="H",D2,E2))

Sheet Annex
A1: Option | B1: 1A | C1: 1B | D1: 1D | E1: 1E | F1: 1G | G1: 1I | H1: 1K | I1: 1L | K1: Valg av sekvens for treerne | T1: Dette er oversikten over alle mulige kombinasjoner av treere. Norge kan havne på 6 forskjellige steder i dette oppsettet
A2: 8 | B2: =_xlfn.XLOOKUP($A$2,$J$4:$J$498,B4:B498,B3) -> Avven | C2: =_xlfn.XLOOKUP($A$2,$J$4:$J$498,C4:C498,C3) -> ter dit | D2: =_xlfn.XLOOKUP($A$2,$J$4:$J$498,D4:D498,D3) -> t valg a | E2: =_xlfn.XLOOKUP($A$2,$J$4:$J$498,E4:E498,E3) -> v åtte | F2: =_xlfn.XLOOKUP($A$2,$J$4:$J$498,F4:F498,F3) -> beste | G2: =_xlfn.XLOOKUP($A$2,$J$4:$J$498,G4:G498,G3) -> treere | H2: =_xlfn.XLOOKUP($A$2,$J$4:$J$498,H4:H498,H3) -> . Stå p | I2: =_xlfn.XLOOKUP($A$2,$J$4:$J$498,I4:I498,I3) -> å! Tipp | T2: Med en tredjeplass kan vi få vinneren av en av seks grupper. Tabllen viser gruppene, og hvor mange varianter som sender oss mot respektive motstander
B3: Avven | C3: ter dit | D3: t valg a | E3: v åtte | F3: beste | G3: treere | H3: . Stå p | I3: å! Tipp | T3: Dvs. 113 av 495 kombinasjoner av 3-ere gir vinneren av Englands gruppe som motstander for 3 i vår gruppe I
A4: 1 | B4: 3E | C4: 3J | D4: 3I | E4: 3F | F4: 3H | G4: 3G | H4: 3L | I4: 3K | J4: =SUM(K4:R4) -> 0 | K4: =COUNTIFS(Grunnspill!$A:$A,Annex!B4) -> 0 | L4: =COUNTIFS(Grunnspill!$A:$A,Annex!C4) -> 0 | M4: =COUNTIFS(Grunnspill!$A:$A,Annex!D4) -> 0 | N4: =COUNTIFS(Grunnspill!$A:$A,Annex!E4) -> 0 | O4: =COUNTIFS(Grunnspill!$A:$A,Annex!F4) -> 0 | P4: =COUNTIFS(Grunnspill!$A:$A,Annex!G4) -> 0 | Q4: =COUNTIFS(Grunnspill!$A:$A,Annex!H4) -> 0 | R4: =COUNTIFS(Grunnspill!$A:$A,Annex!I4) -> 0 | T4: Det er 330 varianter som har med 3-eren i pulje I. Hvilken kombinasjon som blir gjeldende blir altså ikke bestemt før siste kamp er ferdig.
A5: 2 | B5: 3H | C5: 3G | D5: 3I | E5: 3D | F5: 3J | G5: 3F | H5: 3L | I5: 3K | J5: =SUM(K5:R5) -> 0 | K5: =COUNTIFS(Grunnspill!$A:$A,Annex!B5) -> 0 | L5: =COUNTIFS(Grunnspill!$A:$A,Annex!C5) -> 0 | M5: =COUNTIFS(Grunnspill!$A:$A,Annex!D5) -> 0 | N5: =COUNTIFS(Grunnspill!$A:$A,Annex!E5) -> 0 | O5: =COUNTIFS(Grunnspill!$A:$A,Annex!F5) -> 0 | P5: =COUNTIFS(Grunnspill!$A:$A,Annex!G5) -> 0 | Q5: =COUNTIFS(Grunnspill!$A:$A,Annex!H5) -> 0 | R5: =COUNTIFS(Grunnspill!$A:$A,Annex!I5) -> 0
A6: 3 | B6: 3E | C6: 3J | D6: 3I | E6: 3D | F6: 3H | G6: 3G | H6: 3L | I6: 3K | J6: =SUM(K6:R6) -> 0 | K6: =COUNTIFS(Grunnspill!$A:$A,Annex!B6) -> 0 | L6: =COUNTIFS(Grunnspill!$A:$A,Annex!C6) -> 0 | M6: =COUNTIFS(Grunnspill!$A:$A,Annex!D6) -> 0 | N6: =COUNTIFS(Grunnspill!$A:$A,Annex!E6) -> 0 | O6: =COUNTIFS(Grunnspill!$A:$A,Annex!F6) -> 0 | P6: =COUNTIFS(Grunnspill!$A:$A,Annex!G6) -> 0 | Q6: =COUNTIFS(Grunnspill!$A:$A,Annex!H6) -> 0 | R6: =COUNTIFS(Grunnspill!$A:$A,Annex!I6) -> 0 | T6: {=+B1:I1} -> 1A | U6: 1B | V6: 1D | W6: 1E | X6: 1G | Y6: 1I | Z6: 1K | AA6: 1L
A7: 4 | B7: 3E | C7: 3J | D7: 3I | E7: 3D | F7: 3H | G7: 3F | H7: 3L | I7: 3K | J7: =SUM(K7:R7) -> 0 | K7: =COUNTIFS(Grunnspill!$A:$A,Annex!B7) -> 0 | L7: =COUNTIFS(Grunnspill!$A:$A,Annex!C7) -> 0 | M7: =COUNTIFS(Grunnspill!$A:$A,Annex!D7) -> 0 | N7: =COUNTIFS(Grunnspill!$A:$A,Annex!E7) -> 0 | O7: =COUNTIFS(Grunnspill!$A:$A,Annex!F7) -> 0 | P7: =COUNTIFS(Grunnspill!$A:$A,Annex!G7) -> 0 | Q7: =COUNTIFS(Grunnspill!$A:$A,Annex!H7) -> 0 | R7: =COUNTIFS(Grunnspill!$A:$A,Annex!I7) -> 0 | T7: =COUNTIFS(B4:B498,"3I") -> 19 | U7: =COUNTIFS(C4:C498,"3I") -> 14 | V7: =COUNTIFS(D4:D498,"3I") -> 52 | W7: =COUNTIFS(E4:E498,"3I") -> 0 | X7: =COUNTIFS(F4:F498,"3I") -> 41 | Y7: =COUNTIFS(G4:G498,"3I") -> 0 | Z7: =COUNTIFS(H4:H498,"3I") -> 91 | AA7: =COUNTIFS(I4:I498,"3I") -> 113
A8: 5 | B8: 3E | C8: 3G | D8: 3I | E8: 3D | F8: 3J | G8: 3F | H8: 3L | I8: 3K | J8: =SUM(K8:R8) -> 0 | K8: =COUNTIFS(Grunnspill!$A:$A,Annex!B8) -> 0 | L8: =COUNTIFS(Grunnspill!$A:$A,Annex!C8) -> 0 | M8: =COUNTIFS(Grunnspill!$A:$A,Annex!D8) -> 0 | N8: =COUNTIFS(Grunnspill!$A:$A,Annex!E8) -> 0 | O8: =COUNTIFS(Grunnspill!$A:$A,Annex!F8) -> 0 | P8: =COUNTIFS(Grunnspill!$A:$A,Annex!G8) -> 0 | Q8: =COUNTIFS(Grunnspill!$A:$A,Annex!H8) -> 0 | R8: =COUNTIFS(Grunnspill!$A:$A,Annex!I8) -> 0 | T8: {=+Grunnspill!D4:D7} -> Mexico | U8: {=+Grunnspill!D8:D11} -> Canada | V8: {=+Grunnspill!D16:D19} -> USA | X8: {=+Grunnspill!D28:D31} -> Belgia | Z8: {=+Grunnspill!D44:D47} -> Portugal | AA8: {=+Grunnspill!D48:D51} -> England
A9: 6 | B9: 3E | C9: 3G | D9: 3J | E9: 3D | F9: 3H | G9: 3F | H9: 3L | I9: 3K | J9: =SUM(K9:R9) -> 0 | K9: =COUNTIFS(Grunnspill!$A:$A,Annex!B9) -> 0 | L9: =COUNTIFS(Grunnspill!$A:$A,Annex!C9) -> 0 | M9: =COUNTIFS(Grunnspill!$A:$A,Annex!D9) -> 0 | N9: =COUNTIFS(Grunnspill!$A:$A,Annex!E9) -> 0 | O9: =COUNTIFS(Grunnspill!$A:$A,Annex!F9) -> 0 | P9: =COUNTIFS(Grunnspill!$A:$A,Annex!G9) -> 0 | Q9: =COUNTIFS(Grunnspill!$A:$A,Annex!H9) -> 0 | R9: =COUNTIFS(Grunnspill!$A:$A,Annex!I9) -> 0 | T9: Sør-Afrika | U9: Bosnia-Hercegovina | V9: Paraguay | X9: Iran | Z9: DR Kongo | AA9: Kroatia
A10: 7 | B10: 3E | C10: 3G | D10: 3I | E10: 3D | F10: 3H | G10: 3F | H10: 3L | I10: 3K | J10: =SUM(K10:R10) -> 0 | K10: =COUNTIFS(Grunnspill!$A:$A,Annex!B10) -> 0 | L10: =COUNTIFS(Grunnspill!$A:$A,Annex!C10) -> 0 | M10: =COUNTIFS(Grunnspill!$A:$A,Annex!D10) -> 0 | N10: =COUNTIFS(Grunnspill!$A:$A,Annex!E10) -> 0 | O10: =COUNTIFS(Grunnspill!$A:$A,Annex!F10) -> 0 | P10: =COUNTIFS(Grunnspill!$A:$A,Annex!G10) -> 0 | Q10: =COUNTIFS(Grunnspill!$A:$A,Annex!H10) -> 0 | R10: =COUNTIFS(Grunnspill!$A:$A,Annex!I10) -> 0 | T10: Sør-Korea | U10: Qatar | V10: Australia | X10: Egypt | Z10: Usbekistan | AA10: Ghana
A11: 8 | B11: 3E | C11: 3G | D11: 3J | E11: 3D | F11: 3H | G11: 3F | H11: 3L | I11: 3I | J11: =SUM(K11:R11) -> 0 | K11: =COUNTIFS(Grunnspill!$A:$A,Annex!B11) -> 0 | L11: =COUNTIFS(Grunnspill!$A:$A,Annex!C11) -> 0 | M11: =COUNTIFS(Grunnspill!$A:$A,Annex!D11) -> 0 | N11: =COUNTIFS(Grunnspill!$A:$A,Annex!E11) -> 0 | O11: =COUNTIFS(Grunnspill!$A:$A,Annex!F11) -> 0 | P11: =COUNTIFS(Grunnspill!$A:$A,Annex!G11) -> 0 | Q11: =COUNTIFS(Grunnspill!$A:$A,Annex!H11) -> 0 | R11: =COUNTIFS(Grunnspill!$A:$A,Annex!I11) -> 0 | T11: Tsjekkia | U11: Sveits | V11: Tyrkia | X11: New Zealand | Z11: Colombia | AA11: Panama
A12: 9 | B12: 3E | C12: 3G | D12: 3J | E12: 3D | F12: 3H | G12: 3F | H12: 3I | I12: 3K | J12: =SUM(K12:R12) -> 0 | K12: =COUNTIFS(Grunnspill!$A:$A,Annex!B12) -> 0 | L12: =COUNTIFS(Grunnspill!$A:$A,Annex!C12) -> 0 | M12: =COUNTIFS(Grunnspill!$A:$A,Annex!D12) -> 0 | N12: =COUNTIFS(Grunnspill!$A:$A,Annex!E12) -> 0 | O12: =COUNTIFS(Grunnspill!$A:$A,Annex!F12) -> 0 | P12: =COUNTIFS(Grunnspill!$A:$A,Annex!G12) -> 0 | Q12: =COUNTIFS(Grunnspill!$A:$A,Annex!H12) -> 0 | R12: =COUNTIFS(Grunnspill!$A:$A,Annex!I12) -> 0
A13: 10 | B13: 3H | C13: 3G | D13: 3I | E13: 3C | F13: 3J | G13: 3F | H13: 3L | I13: 3K | J13: =SUM(K13:R13) -> 0 | K13: =COUNTIFS(Grunnspill!$A:$A,Annex!B13) -> 0 | L13: =COUNTIFS(Grunnspill!$A:$A,Annex!C13) -> 0 | M13: =COUNTIFS(Grunnspill!$A:$A,Annex!D13) -> 0 | N13: =COUNTIFS(Grunnspill!$A:$A,Annex!E13) -> 0 | O13: =COUNTIFS(Grunnspill!$A:$A,Annex!F13) -> 0 | P13: =COUNTIFS(Grunnspill!$A:$A,Annex!G13) -> 0 | Q13: =COUNTIFS(Grunnspill!$A:$A,Annex!H13) -> 0 | R13: =COUNTIFS(Grunnspill!$A:$A,Annex!I13) -> 0 | T13: I kollone J vil det komme opp ett 8-tall. Det er den fordelingen som blir satt inn i B2:I2
A14: 11 | B14: 3E | C14: 3J | D14: 3I | E14: 3C | F14: 3H | G14: 3G | H14: 3L | I14: 3K | J14: =SUM(K14:R14) -> 0 | K14: =COUNTIFS(Grunnspill!$A:$A,Annex!B14) -> 0 | L14: =COUNTIFS(Grunnspill!$A:$A,Annex!C14) -> 0 | M14: =COUNTIFS(Grunnspill!$A:$A,Annex!D14) -> 0 | N14: =COUNTIFS(Grunnspill!$A:$A,Annex!E14) -> 0 | O14: =COUNTIFS(Grunnspill!$A:$A,Annex!F14) -> 0 | P14: =COUNTIFS(Grunnspill!$A:$A,Annex!G14) -> 0 | Q14: =COUNTIFS(Grunnspill!$A:$A,Annex!H14) -> 0 | R14: =COUNTIFS(Grunnspill!$A:$A,Annex!I14) -> 0 | T14: I B1:I1 står åtte vinnerlag
A15: 12 | B15: 3E | C15: 3J | D15: 3I | E15: 3C | F15: 3H | G15: 3F | H15: 3L | I15: 3K | J15: =SUM(K15:R15) -> 0 | K15: =COUNTIFS(Grunnspill!$A:$A,Annex!B15) -> 0 | L15: =COUNTIFS(Grunnspill!$A:$A,Annex!C15) -> 0 | M15: =COUNTIFS(Grunnspill!$A:$A,Annex!D15) -> 0 | N15: =COUNTIFS(Grunnspill!$A:$A,Annex!E15) -> 0 | O15: =COUNTIFS(Grunnspill!$A:$A,Annex!F15) -> 0 | P15: =COUNTIFS(Grunnspill!$A:$A,Annex!G15) -> 0 | Q15: =COUNTIFS(Grunnspill!$A:$A,Annex!H15) -> 0 | R15: =COUNTIFS(Grunnspill!$A:$A,Annex!I15) -> 0
A16: 13 | B16: 3E | C16: 3G | D16: 3I | E16: 3C | F16: 3J | G16: 3F | H16: 3L | I16: 3K | J16: =SUM(K16:R16) -> 0 | K16: =COUNTIFS(Grunnspill!$A:$A,Annex!B16) -> 0 | L16: =COUNTIFS(Grunnspill!$A:$A,Annex!C16) -> 0 | M16: =COUNTIFS(Grunnspill!$A:$A,Annex!D16) -> 0 | N16: =COUNTIFS(Grunnspill!$A:$A,Annex!E16) -> 0 | O16: =COUNTIFS(Grunnspill!$A:$A,Annex!F16) -> 0 | P16: =COUNTIFS(Grunnspill!$A:$A,Annex!G16) -> 0 | Q16: =COUNTIFS(Grunnspill!$A:$A,Annex!H16) -> 0 | R16: =COUNTIFS(Grunnspill!$A:$A,Annex!I16) -> 0
A17: 14 | B17: 3E | C17: 3G | D17: 3J | E17: 3C | F17: 3H | G17: 3F | H17: 3L | I17: 3K | J17: =SUM(K17:R17) -> 0 | K17: =COUNTIFS(Grunnspill!$A:$A,Annex!B17) -> 0 | L17: =COUNTIFS(Grunnspill!$A:$A,Annex!C17) -> 0 | M17: =COUNTIFS(Grunnspill!$A:$A,Annex!D17) -> 0 | N17: =COUNTIFS(Grunnspill!$A:$A,Annex!E17) -> 0 | O17: =COUNTIFS(Grunnspill!$A:$A,Annex!F17) -> 0 | P17: =COUNTIFS(Grunnspill!$A:$A,Annex!G17) -> 0 | Q17: =COUNTIFS(Grunnspill!$A:$A,Annex!H17) -> 0 | R17: =COUNTIFS(Grunnspill!$A:$A,Annex!I17) -> 0
A18: 15 | B18: 3E | C18: 3G | D18: 3I | E18: 3C | F18: 3H | G18: 3F | H18: 3L | I18: 3K | J18: =SUM(K18:R18) -> 0 | K18: =COUNTIFS(Grunnspill!$A:$A,Annex!B18) -> 0 | L18: =COUNTIFS(Grunnspill!$A:$A,Annex!C18) -> 0 | M18: =COUNTIFS(Grunnspill!$A:$A,Annex!D18) -> 0 | N18: =COUNTIFS(Grunnspill!$A:$A,Annex!E18) -> 0 | O18: =COUNTIFS(Grunnspill!$A:$A,Annex!F18) -> 0 | P18: =COUNTIFS(Grunnspill!$A:$A,Annex!G18) -> 0 | Q18: =COUNTIFS(Grunnspill!$A:$A,Annex!H18) -> 0 | R18: =COUNTIFS(Grunnspill!$A:$A,Annex!I18) -> 0
A19: 16 | B19: 3E | C19: 3G | D19: 3J | E19: 3C | F19: 3H | G19: 3F | H19: 3L | I19: 3I | J19: =SUM(K19:R19) -> 0 | K19: =COUNTIFS(Grunnspill!$A:$A,Annex!B19) -> 0 | L19: =COUNTIFS(Grunnspill!$A:$A,Annex!C19) -> 0 | M19: =COUNTIFS(Grunnspill!$A:$A,Annex!D19) -> 0 | N19: =COUNTIFS(Grunnspill!$A:$A,Annex!E19) -> 0 | O19: =COUNTIFS(Grunnspill!$A:$A,Annex!F19) -> 0 | P19: =COUNTIFS(Grunnspill!$A:$A,Annex!G19) -> 0 | Q19: =COUNTIFS(Grunnspill!$A:$A,Annex!H19) -> 0 | R19: =COUNTIFS(Grunnspill!$A:$A,Annex!I19) -> 0
A20: 17 | B20: 3E | C20: 3G | D20: 3J | E20: 3C | F20: 3H | G20: 3F | H20: 3I | I20: 3K | J20: =SUM(K20:R20) -> 0 | K20: =COUNTIFS(Grunnspill!$A:$A,Annex!B20) -> 0 | L20: =COUNTIFS(Grunnspill!$A:$A,Annex!C20) -> 0 | M20: =COUNTIFS(Grunnspill!$A:$A,Annex!D20) -> 0 | N20: =COUNTIFS(Grunnspill!$A:$A,Annex!E20) -> 0 | O20: =COUNTIFS(Grunnspill!$A:$A,Annex!F20) -> 0 | P20: =COUNTIFS(Grunnspill!$A:$A,Annex!G20) -> 0 | Q20: =COUNTIFS(Grunnspill!$A:$A,Annex!H20) -> 0 | R20: =COUNTIFS(Grunnspill!$A:$A,Annex!I20) -> 0
A21: 18 | B21: 3H | C21: 3G | D21: 3I | E21: 3C | F21: 3J | G21: 3D | H21: 3L | I21: 3K | J21: =SUM(K21:R21) -> 0 | K21: =COUNTIFS(Grunnspill!$A:$A,Annex!B21) -> 0 | L21: =COUNTIFS(Grunnspill!$A:$A,Annex!C21) -> 0 | M21: =COUNTIFS(Grunnspill!$A:$A,Annex!D21) -> 0 | N21: =COUNTIFS(Grunnspill!$A:$A,Annex!E21) -> 0 | O21: =COUNTIFS(Grunnspill!$A:$A,Annex!F21) -> 0 | P21: =COUNTIFS(Grunnspill!$A:$A,Annex!G21) -> 0 | Q21: =COUNTIFS(Grunnspill!$A:$A,Annex!H21) -> 0 | R21: =COUNTIFS(Grunnspill!$A:$A,Annex!I21) -> 0
A22: 19 | B22: 3C | C22: 3J | D22: 3I | E22: 3D | F22: 3H | G22: 3F | H22: 3L | I22: 3K | J22: =SUM(K22:R22) -> 0 | K22: =COUNTIFS(Grunnspill!$A:$A,Annex!B22) -> 0 | L22: =COUNTIFS(Grunnspill!$A:$A,Annex!C22) -> 0 | M22: =COUNTIFS(Grunnspill!$A:$A,Annex!D22) -> 0 | N22: =COUNTIFS(Grunnspill!$A:$A,Annex!E22) -> 0 | O22: =COUNTIFS(Grunnspill!$A:$A,Annex!F22) -> 0 | P22: =COUNTIFS(Grunnspill!$A:$A,Annex!G22) -> 0 | Q22: =COUNTIFS(Grunnspill!$A:$A,Annex!H22) -> 0 | R22: =COUNTIFS(Grunnspill!$A:$A,Annex!I22) -> 0
A23: 20 | B23: 3C | C23: 3G | D23: 3I | E23: 3D | F23: 3J | G23: 3F | H23: 3L | I23: 3K | J23: =SUM(K23:R23) -> 0 | K23: =COUNTIFS(Grunnspill!$A:$A,Annex!B23) -> 0 | L23: =COUNTIFS(Grunnspill!$A:$A,Annex!C23) -> 0 | M23: =COUNTIFS(Grunnspill!$A:$A,Annex!D23) -> 0 | N23: =COUNTIFS(Grunnspill!$A:$A,Annex!E23) -> 0 | O23: =COUNTIFS(Grunnspill!$A:$A,Annex!F23) -> 0 | P23: =COUNTIFS(Grunnspill!$A:$A,Annex!G23) -> 0 | Q23: =COUNTIFS(Grunnspill!$A:$A,Annex!H23) -> 0 | R23: =COUNTIFS(Grunnspill!$A:$A,Annex!I23) -> 0
A24: 21 | B24: 3C | C24: 3G | D24: 3J | E24: 3D | F24: 3H | G24: 3F | H24: 3L | I24: 3K | J24: =SUM(K24:R24) -> 0 | K24: =COUNTIFS(Grunnspill!$A:$A,Annex!B24) -> 0 | L24: =COUNTIFS(Grunnspill!$A:$A,Annex!C24) -> 0 | M24: =COUNTIFS(Grunnspill!$A:$A,Annex!D24) -> 0 | N24: =COUNTIFS(Grunnspill!$A:$A,Annex!E24) -> 0 | O24: =COUNTIFS(Grunnspill!$A:$A,Annex!F24) -> 0 | P24: =COUNTIFS(Grunnspill!$A:$A,Annex!G24) -> 0 | Q24: =COUNTIFS(Grunnspill!$A:$A,Annex!H24) -> 0 | R24: =COUNTIFS(Grunnspill!$A:$A,Annex!I24) -> 0
A25: 22 | B25: 3C | C25: 3G | D25: 3I | E25: 3D | F25: 3H | G25: 3F | H25: 3L | I25: 3K | J25: =SUM(K25:R25) -> 0 | K25: =COUNTIFS(Grunnspill!$A:$A,Annex!B25) -> 0 | L25: =COUNTIFS(Grunnspill!$A:$A,Annex!C25) -> 0 | M25: =COUNTIFS(Grunnspill!$A:$A,Annex!D25) -> 0 | N25: =COUNTIFS(Grunnspill!$A:$A,Annex!E25) -> 0 | O25: =COUNTIFS(Grunnspill!$A:$A,Annex!F25) -> 0 | P25: =COUNTIFS(Grunnspill!$A:$A,Annex!G25) -> 0 | Q25: =COUNTIFS(Grunnspill!$A:$A,Annex!H25) -> 0 | R25: =COUNTIFS(Grunnspill!$A:$A,Annex!I25) -> 0
A26: 23 | B26: 3C | C26: 3G | D26: 3J | E26: 3D | F26: 3H | G26: 3F | H26: 3L | I26: 3I | J26: =SUM(K26:R26) -> 0 | K26: =COUNTIFS(Grunnspill!$A:$A,Annex!B26) -> 0 | L26: =COUNTIFS(Grunnspill!$A:$A,Annex!C26) -> 0 | M26: =COUNTIFS(Grunnspill!$A:$A,Annex!D26) -> 0 | N26: =COUNTIFS(Grunnspill!$A:$A,Annex!E26) -> 0 | O26: =COUNTIFS(Grunnspill!$A:$A,Annex!F26) -> 0 | P26: =COUNTIFS(Grunnspill!$A:$A,Annex!G26) -> 0 | Q26: =COUNTIFS(Grunnspill!$A:$A,Annex!H26) -> 0 | R26: =COUNTIFS(Grunnspill!$A:$A,Annex!I26) -> 0
... A498: 495 | B498: 3H | C498: 3G | D498: 3B | E498: 3C | F498: 3A | G498: 3F | H498: 3D | I498: 3E | J498: =SUM(K498:R498) -> 0 | K498: =COUNTIFS(Grunnspill!$A:$A,Annex!B498) -> 0 | L498: =COUNTIFS(Grunnspill!$A:$A,Annex!C498) -> 0 | M498: =COUNTIFS(Grunnspill!$A:$A,Annex!D498) -> 0 | N498: =COUNTIFS(Grunnspill!$A:$A,Annex!E498) -> 0 | O498: =COUNTIFS(Grunnspill!$A:$A,Annex!F498) -> 0 | P498: =COUNTIFS(Grunnspill!$A:$A,Annex!G498) -> 0 | Q498: =COUNTIFS(Grunnspill!$A:$A,Annex!H498) -> 0 | R498: =COUNTIFS(Grunnspill!$A:$A,Annex!I498) -> 0
